Workbook

Sheet Standings
B1: DIVISION 1
M2: Tiebreakers
B3: Lg 1-1 | C3: Pts | D3: Avg | E3: 1st | F3: 2nd | G3: 3rd | H3: 4th | I3: 1st | J3: 2nd | K3: 3rd | N3: (if needed - i.e. to determine promotion/relegation)
B4: LeonC | C4: =E4*6+F4*3+G4*1+I4*5+J4*2 -> 26 | D4: =if(sum(E4:K4)>0,C4/sum(E4:K4),) -> 3.7142857 | E4: 2 | G4: 2 | I4: 2 | J4: 1 | M4: 1 | N4: Re-score all games using +1 format (e.g. 3,2,1,0 for 4p and 2,1,0 for 3p games) Higher score wins tiebreaker.
B5: AaronGreen | C5: =E5*6+F5*3+G5*1+I5*5+J5*2 -> 25 | D5: =if(sum(E5:K5)>0,C5/sum(E5:K5),) -> 3.5714286 | E5: 2 | F5: 1 | G5: 1 | I5: 1 | J5: 2 | M5: 2 | N5: Head-to-Head: For games tied players met, remove all others. Player with more wins, wins tiebreaker.
B6: Toper | C6: =E6*6+F6*3+G6*1+I6*5+J6*2 -> 22 | D6: =if(sum(E6:K6)>0,C6/sum(E6:K6),) -> 3.1428571 | F6: 4 | I6: 2 | K6: 1 | M6: 3 | N6: Strength of Schedule (N/A for 7p divisions, since everyone plays everyone equal times)
B7: Palino | C7: =E7*6+F7*3+G7*1+I7*5+J7*2 -> 17 | D7: =if(sum(E7:K7)>0,C7/sum(E7:K7),) -> 2.4285714 | E7: 1 | G7: 1 | H7: 2 | I7: 2 | K7: 1 | N7: Add up total points in Standings of all opponents (doubling/tripling if you met twice/thrice).
B8: JCleek | C8: =E8*6+F8*3+G8*1+I8*5+J8*2 -> 11 | D8: =if(sum(E8:K8)>0,C8/sum(E8:K8),) -> 1.5714286 | E8: 1 | F8: 1 | H8: 2 | J8: 1 | K8: 2 | N8: Higher points = tougher schedule and wins tiebreaker.
B9: Grogmir | C9: =E9*6+F9*3+G9*1+I9*5+J9*2 -> 9 | D9: =if(sum(E9:K9)>0,C9/sum(E9:K9),) -> 1.2857143 | E9: 1 | F9: 1 | H9: 2 | K9: 3 | M9: 4 | N9: Percent of winning score: Divide player score by top score of each game. Add up all 7. Higher number wins.
B10: BlixLT | C10: =E10*6+F10*3+G10*1+I10*5+J10*2 -> 9 | D10: =if(sum(E10:K10)>0,C10/sum(E10:K10),) -> 1.2857143 | G10: 3 | H10: 1 | J10: 3 | M10: 5 | N10: Coin flip
B11: =sum(C4:C10)/119 -> 1 | E11: Complete | M11: Note: | N11: For more than 2 players: include all players until ONE is eliminated. Start back at #1 with remaining players.
B12: DIVISION 2 | I12: (2 Leagues - No Wild Card)
B14: Lg 2-1 | C14: Pts | D14: Avg | E14: 1st | F14: 2nd | G14: 3rd | H14: 4th | I14: 1st | J14: 2nd | K14: 3rd | M14: Lg 2-2 | N14: Pts | O14: Avg | Q14: 1st | R14: 2nd | S14: 3rd | T14: 4th | U14: 1st | V14: 2nd | W14: 3rd
B15: Frotes | C15: =E15*6+F15*3+G15*1+I15*5+J15*2 -> 33 | D15: =if(sum(E15:K15)>0,C15/sum(E15:K15),) -> 4.7142857 | E15: 2 | F15: 2 | I15: 3 | M15: ChipsAhoya | N15: =Q15*6+R15*3+S15*1+U15*5+V15*2 -> 29.5 | O15: =if(sum(Q15:W15)>0,N15/sum(Q15:W15),) -> 4.2142857 | Q15: 3 | R15: 1 | U15: 1.5 | V15: 0.5 | W15: 1
B16: FlyingDutchman | C16: =E16*6+F16*3+G16*1+I16*5+J16*2 -> 27 | D16: =if(sum(E16:K16)>0,C16/sum(E16:K16),) -> 3.8571429 | E16: 2 | F16: 1 | H16: 1 | I16: 2 | J16: 1 | M16: Aquir | N16: =Q16*6+R16*3+S16*1+U16*5+V16*2 -> 26 | O16: =if(sum(Q16:W16)>0,N16/sum(Q16:W16),) -> 3.7142857 | Q16: 2 | R16: 1 | S16: 1 | U16: 2 | W16: 1
B17: GregoryD | C17: =E17*6+F17*3+G17*1+I17*5+J17*2 -> 21 | D17: =if(sum(E17:K17)>0,C17/sum(E17:K17),) -> 3 | E17: 1 | F17: 2.5 | G17: 0.5 | I17: 1 | J17: 1 | K17: 1 | M17: qhung49 | N17: =Q17*6+R17*3+S17*1+U17*5+V17*2 -> 24.5 | O17: =if(sum(Q17:W17)>0,N17/sum(Q17:W17),) -> 3.5 | Q17: 2 | R17: 1 | S17: 1 | U17: 1.5 | V17: 0.5 | W17: 1
B18: albinsix | C18: =E18*6+F18*3+G18*1+I18*5+J18*2 -> 14 | D18: =if(sum(E18:K18)>0,C18/sum(E18:K18),) -> 2 | E18: 1 | F18: 1 | G18: 1 | H18: 1 | J18: 2 | K18: 1 | M18: nachof | N18: =Q18*6+R18*3+S18*1+U18*5+V18*2 -> 11 | O18: =if(sum(Q18:W18)>0,N18/sum(Q18:W18),) -> 1.5714286 | S18: 2 | T18: 2 | U18: 1 | V18: 2
B19: Wartin | C19: =E19*6+F19*3+G19*1+I19*5+J19*2 -> 11 | D19: =if(sum(E19:K19)>0,C19/sum(E19:K19),) -> 1.5714286 | E19: 1 | F19: 0.5 | G19: 1.5 | H19: 1 | J19: 1 | K19: 2 | M19: jamiu5 | N19: =Q19*6+R19*3+S19*1+U19*5+V19*2 -> 10 | O19: =if(sum(Q19:W19)>0,N19/sum(Q19:W19),) -> 1.4285714 | R19: 2 | T19: 2 | V19: 2 | W19: 1
B20: Andras | C20: =E20*6+F20*3+G20*1+I20*5+J20*2 -> 9 | D20: =if(sum(E20:K20)>0,C20/sum(E20:K20),) -> 1.2857143 | G20: 2 | H20: 2 | I20: 1 | J20: 1 | K20: 1 | M20: norkle | N20: =Q20*6+R20*3+S20*1+U20*5+V20*2 -> 9 | O20: =if(sum(Q20:W20)>0,N20/sum(Q20:W20),) -> 1.2857143 | R20: 1 | S20: 1 | T20: 2 | U20: 1 | W20: 2
B21: Cefrebunda | C21: =E21*6+F21*3+G21*1+I21*5+J21*2 -> 4 | D21: =if(sum(E21:K21)>0,C21/sum(E21:K21),) -> 0.57142857 | G21: 2 | H21: 2 | J21: 1 | K21: 2 | M21: Greenilocks | N21: =Q21*6+R21*3+S21*1+U21*5+V21*2 -> 9 | O21: =if(sum(Q21:W21)>0,N21/sum(Q21:W21),) -> 1.2857143 | R21: 1 | S21: 2 | T21: 1 | V21: 2 | W21: 1
B22: =sum(C15:C21)/119 -> 1 | E22: Complete | M22: =sum(N15:N21)/119 -> 1 | Q22: Complete
B23: DIVISION 3 | I23: (3 Leagues - 1 Wild Card)
B25: Lg 3-1 | C25: Pts | D25: Avg | E25: 1st | F25: 2nd | G25: 3rd | H25: 4th | I25: 1st | J25: 2nd | K25: 3rd | M25: Lg 3-2 | N25: Pts | O25: Avg | Q25: 1st | R25: 2nd | S25: 3rd | T25: 4th | U25: 1st | V25: 2nd | W25: 3rd | Y25: Lg 3-3 | Z25: Pts | AA25: Avg | AB25: 1st | AC25: 2nd | AD25: 3rd | AE25: 4th | AF25: 1st | AG25: 2nd | AH25: 3rd
B26: pajada | C26: =E26*6+F26*3+G26*1+I26*5+J26*2 -> 34 | D26: =if(sum(E26:K26)>0,C26/sum(E26:K26),) -> 4.8571429 | E26: 4 | I26: 2 | K26: 1 | M26: JeremyBrokaw | N26: =Q26*6+R26*3+S26*1+U26*5+V26*2 -> 39 | O26: =if(sum(Q26:W26)>0,N26/sum(Q26:W26),) -> 5.5714286 | Q26: 4 | U26: 3 | Y26: hihihiji | Z26: =AB26*6+AC26*3+AD26*1+AF26*5+AG26*2 -> 33 | AA26: =if(sum(AB26:AH26)>0,Z26/sum(AB26:AH26),) -> 4.7142857 | AB26: 3 | AC26: 1 | AF26: 2 | AG26: 1
B27: swxnw | C27: =E27*6+F27*3+G27*1+I27*5+J27*2 -> 23 | D27: =if(sum(E27:K27)>0,C27/sum(E27:K27),) -> 3.2857143 | E27: 1 | F27: 1 | G27: 2 | I27: 2 | J27: 1 | M27: invalidName | N27: =Q27*6+R27*3+S27*1+U27*5+V27*2 -> 24 | O27: =if(sum(Q27:W27)>0,N27/sum(Q27:W27),) -> 3.4285714 | Q27: 1 | R27: 2 | T27: 1 | U27: 2 | V27: 1 | Y27: Woodenman | Z27: =AB27*6+AC27*3+AD27*1+AF27*5+AG27*2 -> 28 | AA27: =if(sum(AB27:AH27)>0,Z27/sum(AB27:AH27),) -> 4 | AB27: 2 | AC27: 1 | AD27: 1 | AF27: 2 | AG27: 1
B28: PhiTrigger | C28: =E28*6+F28*3+G28*1+I28*5+J28*2 -> 20 | D28: =if(sum(E28:K28)>0,C28/sum(E28:K28),) -> 2.8571429 | E28: 2 | F28: 1 | H28: 1 | I28: 1 | K28: 2 | M28: takusto_ii | N28: =Q28*6+R28*3+S28*1+U28*5+V28*2 -> 22 | O28: =if(sum(Q28:W28)>0,N28/sum(Q28:W28),) -> 3.1428571 | Q28: 1 | R28: 3 | U28: 1 | V28: 1 | W28: 1 | Y28: Circadia | Z28: =AB28*6+AC28*3+AD28*1+AF28*5+AG28*2 -> 28 | AA28: =if(sum(AB28:AH28)>0,Z28/sum(AB28:AH28),) -> 4 | AB28: 2 | AC28: 1 | AD28: 1 | AF28: 2 | AG28: 1
B29: bcnoexceptions | C29: =E29*6+F29*3+G29*1+I29*5+J29*2 -> 17 | D29: =if(sum(E29:K29)>0,C29/sum(E29:K29),) -> 2.4285714 | F29: 2 | G29: 2 | I29: 1 | J29: 2 | M29: Ivantz | N29: =Q29*6+R29*3+S29*1+U29*5+V29*2 -> 16 | O29: =if(sum(Q29:W29)>0,N29/sum(Q29:W29),) -> 2.2857143 | Q29: 1 | S29: 1 | T29: 2 | U29: 1 | V29: 2 | Y29: Werlix | Z29: =AB29*6+AC29*3+AD29*1+AF29*5+AG29*2 -> 13 | AA29: =if(sum(AB29:AH29)>0,Z29/sum(AB29:AH29),) -> 1.8571429 | AC29: 1 | AD29: 3 | AF29: 1 | AG29: 1 | AH29: 1
B30: FabioMP | C30: =E30*6+F30*3+G30*1+I30*5+J30*2 -> 11 | D30: =if(sum(E30:K30)>0,C30/sum(E30:K30),) -> 1.5714286 | F30: 2 | G30: 1 | H30: 1 | J30: 2 | K30: 1 | M30: Rollduptrips | N30: =Q30*6+R30*3+S30*1+U30*5+V30*2 -> 11 | O30: =if(sum(Q30:W30)>0,N30/sum(Q30:W30),) -> 1.5714286 | R30: 2 | S30: 1 | T30: 1 | V30: 2 | W30: 1 | Y30: funkenschlag | Z30: =AB30*6+AC30*3+AD30*1+AF30*5+AG30*2 -> 11 | AA30: =if(sum(AB30:AH30)>0,Z30/sum(AB30:AH30),) -> 1.5714286 | AC30: 3 | AE30: 1 | AG30: 1 | AH30: 2
B31: nasing | C31: =E31*6+F31*3+G31*1+I31*5+J31*2 -> 11 | D31: =if(sum(E31:K31)>0,C31/sum(E31:K31),) -> 1.5714286 | F31: 1 | G31: 1 | H31: 2 | I31: 1 | J31: 1 | K31: 1 | M31: checkmate4200 | N31: =Q31*6+R31*3+S31*1+U31*5+V31*2 -> 6 | O31: =if(sum(Q31:W31)>0,N31/sum(Q31:W31),) -> 0.85714286 | S31: 4 | V31: 1 | W31: 2 | Y31: Fad23 | Z31: =AB31*6+AC31*3+AD31*1+AF31*5+AG31*2 -> 5 | AA31: =if(sum(AB31:AH31)>0,Z31/sum(AB31:AH31),) -> 0.71428571 | AD31: 1 | AE31: 3 | AG31: 2 | AH31: 1
B32: rporrini | C32: =E32*6+F32*3+G32*1+I32*5+J32*2 -> 3 | D32: =if(sum(E32:K32)>0,C32/sum(E32:K32),) -> 0.42857143 | G32: 1 | H32: 3 | J32: 1 | K32: 2 | M32: demianv | N32: =Q32*6+R32*3+S32*1+U32*5+V32*2 -> 1 | O32: =if(sum(Q32:W32)>0,N32/sum(Q32:W32),) -> 0.14285714 | S32: 1 | T32: 3 | W32: 3 | Y32: Flynn | Z32: =AB32*6+AC32*3+AD32*1+AF32*5+AG32*2 -> 1 | AA32: =if(sum(AB32:AH32)>0,Z32/sum(AB32:AH32),) -> 0.14285714 | AD32: 1 | AE32: 3 | AH32: 3
B33: =sum(C26:C32)/119 -> 1 | E33: Complete | M33: =sum(N26:N32)/119 -> 1 | Q33: Complete | Y33: =sum(Z26:Z32)/119 -> 1 | AB33: Complete
B34: DIVISION 4 | I34: (Only 2 Leagues - 3 promoted from each league)
B36: Lg 4-1 | C36: Pts | D36: Avg | E36: 1st | F36: 2nd | G36: 3rd | H36: 4th | I36: 1st | J36: 2nd | K36: 3rd | M36: Lg 4-2 | N36: Pts | O36: Avg | Q36: 1st | R36: 2nd | S36: 3rd | T36: 4th | U36: 1st | V36: 2nd | W36: 3rd
B37: robster | C37: =E37*6+F37*3+G37*1+I37*5+J37*2 -> 33 | D37: =if(sum(E37:K37)>0,C37/sum(E37:K37),) -> 4.7142857 | E37: 3 | F37: 1 | I37: 2 | J37: 1 | M37: DrRerNate | N37: =Q37*6+R37*3+S37*1+U37*5+V37*2 -> 33 | O37: =if(sum(Q37:W37)>0,N37/sum(Q37:W37),) -> 4.7142857 | Q37: 3 | T37: 1 | U37: 3
B38: Pandaiga | C38: =E38*6+F38*3+G38*1+I38*5+J38*2 -> 28 | D38: =if(sum(E38:K38)>0,C38/sum(E38:K38),) -> 4 | E38: 1 | F38: 2 | G38: 1 | I38: 3 | M38: JimmyLin | N38: =Q38*6+R38*3+S38*1+U38*5+V38*2 -> 25.5 | O38: =if(sum(Q38:W38)>0,N38/sum(Q38:W38),) -> 3.6428571 | Q38: 1.5 | R38: 2.5 | U38: 1 | V38: 2
B39: Thomas91 | C39: =E39*6+F39*3+G39*1+I39*5+J39*2 -> 28 | D39: =if(sum(E39:K39)>0,C39/sum(E39:K39),) -> 4 | E39: 3 | G39: 1 | I39: 1 | J39: 2 | M39: Sjir | N39: =Q39*6+R39*3+S39*1+U39*5+V39*2 -> 25 | O39: =if(sum(Q39:W39)>0,N39/sum(Q39:W39),) -> 3.5714286 | Q39: 2 | R39: 2 | U39: 1 | V39: 1 | W39: 1
B40: Chul | C40: =E40*6+F40*3+G40*1+I40*5+J40*2 -> 13 | D40: =if(sum(E40:K40)>0,C40/sum(E40:K40),) -> 1.8571429 | F40: 1 | G40: 3 | I40: 1 | J40: 1 | K40: 1 | M40: kissfish | N40: =Q40*6+R40*3+S40*1+U40*5+V40*2 -> 13.5 | O40: =if(sum(Q40:W40)>0,N40/sum(Q40:W40),) -> 1.9285714 | Q40: 0.5 | R40: 1.5 | S40: 2 | V40: 2 | W40: 1
B41: Monik | C41: =E41*6+F41*3+G41*1+I41*5+J41*2 -> 13 | D41: =if(sum(E41:K41)>0,C41/sum(E41:K41),) -> 1.8571429 | F41: 3 | H41: 1 | J41: 2 | K41: 1 | M41: BillyPilgrim | N41: =Q41*6+R41*3+S41*1+U41*5+V41*2 -> 9 | O41: =if(sum(Q41:W41)>0,N41/sum(Q41:W41),) -> 1.2857143 | S41: 2 | T41: 2 | U41: 1 | V41: 1 | W41: 1
B42: 12thManStanding | C42: =E42*6+F42*3+G42*1+I42*5+J42*2 -> 4 | D42: =if(sum(E42:K42)>0,C42/sum(E42:K42),) -> 0.57142857 | G42: 2 | H42: 2 | J42: 1 | K42: 2 | M42: Peaceminusone | N42: =Q42*6+R42*3+S42*1+U42*5+V42*2 -> 7 | O42: =if(sum(Q42:W42)>0,N42/sum(Q42:W42),) -> 1 | S42: 2 | T42: 2 | U42: 1 | W42: 2
B43: Eroticus | C43: =E43*6+F43*3+G43*1+I43*5+J43*2 -> 0 | D43: =if(sum(E43:K43)>0,C43/sum(E43:K43),) -> 0 | H43: 4 | K43: 3 | M43: Backburner | N43: =Q43*6+R43*3+S43*1+U43*5+V43*2 -> 6 | O43: =if(sum(Q43:W43)>0,N43/sum(Q43:W43),) -> 0.85714286 | R43: 1 | S43: 1 | T43: 2 | V43: 1 | W43: 2
...

Sheet Schedule
B2: ** LEAGUE 1-1 **
B3: 43226 | D3: =B3+7 -> 43233 | F3: =D3+7 -> 43240 | H3: =F3+7 -> 43247 | J3: =H3+7 -> 43254 | L3: =J3+7 -> 43261 | N3: =L3+7 -> 43268
B4: gm 1a | D4: gm 2a | F4: gm 3a | H4: gm 4a | J4: gm 5a | L4: gm 6a | N4: gm 7a
B5: LeonC | C5: 158 | D5: =B8 -> AaronGreen | E5: 171 | F5: =B12 -> Grogmir | G5: 157 | H5: =B11 -> JCleek | I5: 0 | J5: =B6 -> Palino | K5: 186 | L5: =B10 -> Toper | M5: 186 | N5: =B7 -> BlixLT | O5: 227
B6: Palino | C6: 107 | D6: =B5 -> LeonC | E6: 141 | F6: =B6 -> Palino | G6: 147 | H6: =B7 -> BlixLT | I6: 213 | J6: =B8 -> AaronGreen | K6: 234 | L6: =B7 -> BlixLT | M6: 171 | N6: =B8 -> AaronGreen | O6: 294
B7: BlixLT | C7: 103 | D7: =B10 -> Toper | E7: 160 | F7: =B11 -> JCleek | G7: 202 | H7: =B10 -> Toper | I7: 214 | J7: =B10 -> Toper | K7: 245 | L7: =B5 -> LeonC | M7: 204 | N7: =B11 -> JCleek | O7: 239
B8: AaronGreen | C8: 156 | D8: =B11 -> JCleek | E8: 0 | F8: =B5 -> LeonC | G8: 153 | H8: =B6 -> Palino | I8: 219 | J8: =B12 -> Grogmir | K8: 288 | L8: =B12 -> Grogmir | M8: 169 | N8: =B12 -> Grogmir | O8: 210
B9: gm 1b | D9: gm 2b | F9: gm 3b | H9: gm 4b | J9: gm 5b | L9: gm 6b | N9: gm 7b
B10: Toper | C10: 204 | D10: =B6 -> Palino | E10: 163 | F10: =B7 -> BlixLT | G10: 100 | H10: =B12 -> Grogmir | I10: 92 | J10: =B11 -> JCleek | K10: 103 | L10: =B8 -> AaronGreen | M10: 130 | N10: =B5 -> LeonC | O10: 171
B11: JCleek | C11: 182 | D11: =B7 -> BlixLT | E11: 162 | F11: =B8 -> AaronGreen | G11: 141 | H11: =B8 -> AaronGreen | I11: 102 | J11: =B7 -> BlixLT | K11: 108 | L11: =B6 -> Palino | M11: 160 | N11: =B6 -> Palino | O11: 139
B12: Grogmir | C12: 175 | D12: =B12 -> Grogmir | E12: 148 | F12: =B10 -> Toper | G12: 74 | H12: =B5 -> LeonC | I12: 121 | J12: =B5 -> LeonC | K12: 169 | L12: =B11 -> JCleek | M12: 80 | N12: =B10 -> Toper | O12: 175
B14: ** LEAGUE 2-1 **
B15: =B3 -> 43226 | D15: =B15+7 -> 43233 | F15: =D15+7 -> 43240 | H15: =F15+7 -> 43247 | J15: =H15+7 -> 43254 | L15: =J15+7 -> 43261 | N15: =L15+7 -> 43268
B16: gm 1a | D16: gm 2a | F16: gm 3a | H16: gm 4a | J16: gm 5a | L16: gm 6a | N16: gm 7a
B17: Frotes | C17: 179 | D17: =B20 -> Wartin | E17: 188 | F17: =B24 -> albinsix | G17: 96 | H17: =B23 -> Cefrebunda | I17: 117 | J17: =B18 -> FlyingDutchman | K17: 156 | L17: =B22 -> Andras | M17: 0 | N17: =B19 -> GregoryD | O17: 184
B18: FlyingDutchman | C18: 102 | D18: =B17 -> Frotes | E18: 166 | F18: =B18 -> FlyingDutchman | G18: 211 | H18: =B19 -> GregoryD | I18: 230 | J18: =B20 -> Wartin | K18: 114 | L18: =B19 -> GregoryD | M18: 195 | N18: =B20 -> Wartin | O18: 164
B19: GregoryD | C19: 154 | D19: =B22 -> Andras | E19: 149 | F19: =B23 -> Cefrebunda | G19: 124 | H19: =B22 -> Andras | I19: 147 | J19: =B22 -> Andras | K19: 112 | L19: =B17 -> Frotes | M19: 223 | N19: =B23 -> Cefrebunda | O19: 180
B20: Wartin | C20: 154 | D20: =B23 -> Cefrebunda | E20: 104 | F20: =B17 -> Frotes | G20: 185 | H20: =B18 -> FlyingDutchman | I20: 191 | J20: =B24 -> albinsix | K20: 124 | L20: =B24 -> albinsix | M20: 111 | N20: =B24 -> albinsix | O20: 188
B21: gm 1b | D21: gm 2b | F21: gm 3b | H21: gm 4b | J21: gm 5b | L21: gm 6b | N21: gm 7b
B22: Andras | C22: 154 | D22: =B18 -> FlyingDutchman | E22: 167 | F22: =B19 -> GregoryD | G22: 138 | H22: =B24 -> albinsix | I22: 99 | J22: =B23 -> Cefrebunda | K22: 103 | L22: =B20 -> Wartin | M22: 146 | N22: =B17 -> Frotes | O22: 189
B23: Cefrebunda | C23: 103 | D23: =B19 -> GregoryD | E23: 150 | F23: =B20 -> Wartin | G23: 98 | H23: =B20 -> Wartin | I23: 0 | J23: =B19 -> GregoryD | K23: 97 | L23: =B18 -> FlyingDutchman | M23: 190 | N23: =B18 -> FlyingDutchman | O23: 77
B24: albinsix | C24: 123 | D24: =B24 -> albinsix | E24: 108 | F24: =B22 -> Andras | G24: 110 | H24: =B17 -> Frotes | I24: 106 | J24: =B17 -> Frotes | K24: 184 | L24: =B23 -> Cefrebunda | M24: 68 | N24: =B22 -> Andras | O24: 0
B26: ** LEAGUE 2-2 **
B27: =B3 -> 43226 | D27: =B27+7 -> 43233 | F27: =D27+7 -> 43240 | H27: =F27+7 -> 43247 | J27: =H27+7 -> 43254 | L27: =J27+7 -> 43261 | N27: =L27+7 -> 43268
B28: gm 1a | D28: gm 2a | F28: gm 3a | H28: gm 4a | J28: gm 5a | L28: gm 6a | N28: gm 7a
B29: qhung49 | C29: 169 | D29: =B32 -> ChipsAhoya | E29: 184 | F29: =B36 -> norkle | G29: 198 | H29: =B35 -> Greenilocks | I29: 225 | J29: =B30 -> Aquir | K29: 171 | L29: =B34 -> nachof | M29: 155 | N29: =B31 -> jamiu5 | O29: 186
B30: Aquir | C30: 155 | D30: =B29 -> qhung49 | E30: 202 | F30: =B30 -> Aquir | G30: 247 | H30: =B31 -> jamiu5 | I30: 275 | J30: =B32 -> ChipsAhoya | K30: 182 | L30: =B31 -> jamiu5 | M30: 0 | N30: =B32 -> ChipsAhoya | O30: 232
B31: jamiu5 | C31: 144 | D31: =B34 -> nachof | E31: 106 | F31: =B35 -> Greenilocks | G31: 232 | H31: =B34 -> nachof | I31: 198 | J31: =B34 -> nachof | K31: 103 | L31: =B29 -> qhung49 | M31: 191 | N31: =B35 -> Greenilocks | O31: 130
B32: ChipsAhoya | C32: 178 | D32: =B35 -> Greenilocks | E32: 101 | F32: =B29 -> qhung49 | G32: 215 | H32: =B30 -> Aquir | I32: 310 | J32: =B36 -> norkle | K32: 108 | L32: =B36 -> norkle | M32: 189 | N32: =B36 -> norkle | O32: 0
B33: gm 1b | D33: gm 2b | F33: gm 3b | H33: gm 4b | J33: gm 5b | L33: gm 6b | N33: gm 7b
B34: nachof | C34: 170 | D34: =B30 -> Aquir | E34: 164 | F34: =B31 -> jamiu5 | G34: 205 | H34: =B36 -> norkle | I34: 90 | J34: =B35 -> Greenilocks | K34: 166 | L34: =B32 -> ChipsAhoya | M34: 183 | N34: =B29 -> qhung49 | O34: 40
B35: Greenilocks | C35: 163 | D35: =B31 -> jamiu5 | E35: 155 | F35: =B32 -> ChipsAhoya | G35: 195 | H35: =B32 -> ChipsAhoya | I35: 153 | J35: =B31 -> jamiu5 | K35: 150 | L35: =B30 -> Aquir | M35: 134 | N35: =B30 -> Aquir | O35: 147
B36: norkle | C36: 201 | D36: =B36 -> norkle | E36: 148 | F36: =B34 -> nachof | G36: 235 | H36: =B29 -> qhung49 | I36: 153 | J36: =B29 -> qhung49 | K36: 184 | L36: =B35 -> Greenilocks | M36: 168 | N36: =B34 -> nachof | O36: 91
B38: ** LEAGUE 3-1 **
B39: =B3 -> 43226 | D39: =B39+7 -> 43233 | F39: =D39+7 -> 43240 | H39: =F39+7 -> 43247 | J39: =H39+7 -> 43254 | L39: =J39+7 -> 43261 | N39: =L39+7 -> 43268
B40: gm 1a | D40: gm 2a | F40: gm 3a | H40: gm 4a | J40: gm 5a | L40: gm 6a | N40: gm 7a
B41: FabioMP | C41: 189 | D41: =B44 -> swxnw | E41: 150 | F41: =B48 -> nasing | G41: 241 | H41: =B47 -> pajada | I41: 233 | J41: =B42 -> rporrini | K41: 142 | L41: =B46 -> PhiTrigger | M41: 148 | N41: =B43 -> bcnoexceptions | O41: 211
B42: rporrini | C42: 102 | D42: =B41 -> FabioMP | E42: 174 | F42: =B42 -> rporrini | G42: 128 | H42: =B43 -> bcnoexceptions | I42: 187 | J42: =B44 -> swxnw | K42: 202 | L42: =B43 -> bcnoexceptions | M42: 101 | N42: =B44 -> swxnw | O42: 132
B43: bcnoexceptions | C43: 176 | D43: =B46 -> PhiTrigger | E43: 53 | F43: =B47 -> pajada | G43: 261 | H43: =B46 -> PhiTrigger | I43: 206 | J43: =B46 -> PhiTrigger | K43: 248 | L43: =B41 -> FabioMP | M43: 86 | N43: =B47 -> pajada | O43: 261
B44: swxnw | C44: 210 | D44: =B47 -> pajada | E44: 177 | F44: =B41 -> FabioMP | G44: 171 | H44: =B42 -> rporrini | I44: 43 | J44: =B48 -> nasing | K44: 92 | L44: =B48 -> nasing | M44: 88 | N44: =B48 -> nasing | O44: 118
...

Sheet Rules
B1: TOURNAMENT RULES
B2: (see "Player Responsibility" below to see what's required)
B3: Tournament structure | E3: (Adopted from TM Tours)
B4: •The tournament consists of divisions and each division contains a number of leagues.
B6: •There is one league in the first (top) division, two in the second, increasing by the fibonacci sequence (1,2,3,5,8,13,etc).
B9: •Each league normally consists of seven players. Some of the lowest leagues may contain eight or nine, if the number of signed up players for a season is not divisible by seven.
B13: League play
B14: •Each player will play four 4-player games and three 3-player games (7 total games), over four months (3 seasons per year)
B15: •Players start exactly one game every Sunday for seven consecutive weeks.
B16: •Every player in a league will meet everyone else exactly three times (twice in 4-player games; once in 3-player games)
B18: •Note: in eight and nine player leagues it is impossible to meet eveyrone 3 times. Each player still plays 7 games, but over 8 weeks.
B22: Scoring
B23: The scoring depends solely on final positions in the games. Each position scores the following amount of points:
B25: 4-player | D25: 3-player
B26: 1st = 6 points | D26: 1st = 5 points
B27: 2nd = 3 points | D27: 2nd = 2 points
B28: 3rd = 1 point | D28: 3rd = 0 points
B29: 4th = 0 points
B30: •If several players finish in the same position in a game, they split the points for the positions between them.
B32: Example: If two players share the second position (4p), they will both get 2 points.
B34: •Games unfinished by the sign-up deadline of the next season will report the current "in-game scores" (e.g. in age III) and score half the normal "standings points", with last place going negative a half point:
B38: 4 Player: 3 <> 1.5 <> 0.5 <> -0.5
B39: 3 Player: 2.5 <> 1 <> -0.5
B40: Game Rules
B41: •Sign-up in the FB group: Through the Ages: A New Story of Civilization International Championship
B43: •All games to be played in the official TTA app. (also steam?)
B44: •Digital rules (not table top)
B45: •Clock: default async (24 hr per move)
B47: Promotion / Relegation
... B116: •Strike: anything else the group votes to be counted as a strike, even if voted retroactively.

Sheet Instructions
A1: Instructions to the admin for starting a new season =)
A2: Complete in order:
A3: 0 | C3: START!!
C4: Each season starts on the first Sunday of these months: Jan, May, Sep (4 months per season, exactly 3 seasons per year)
A6: 1 | C6: Copy "End List" of players from prior season. Paste (value only) this in tab "Start List", column "Loading List"
A8: 2 | C8: Finalize list of entrants
B9: a | C9: Leaving players: Anyone not returning gets deleted from the "Loading List", leaving an empty cell where their name used to be.
B11: b | C11: Returning entrants (who skipped last season): Enter same level (and never higher) as most recent season played by filling gaps left in step 2-a. If no gaps to fill, they are moved down 1 division level, and all others will move down accordingly.
B14: c | C14: If applicable, remove any remaining gaps by sliding all players up to fill the empty slots.
B15: d | C15: New entrants: Add to bottom of "Loading List" (see point 1, above)
B16: e | C16: Paste this "Loading List" in the column "Name". The "Standings" and "Schedule" tabs should be completely updated now.
B18: f | C18: Note: for scaling (having 8 or 9 in one division) the "Standings" and "Schedule" will have to be altered to reflect the correct number and scheduling for the affected divisions.
A20: 3 | C20: "Standings" tab: Need to copy and "paste values only" all names in divisions (to break the formula that drew the names from the "Start List"). (can do one entire column at a time)
A22: 4 | C22: "Schedule" tab: Similar to step 3 above, need to copy and "paste values only" all names in the schedule under the first game only (columb B). Also update first date and all should auto-fill.
A23: 5 | C23: "End List" tab: never edit this tab. It is used to copy this list and paste into next season as a starting point (see point 1, above and also 2-f, for scaling).
C25: ** Setup Complete ** Season Begins **
A26: 6 | C26: "Schedule" tab - how to update:
C27: For each completed game, put the scores next to the appropriate player. For resignations, give the player 10 points less than the player one place higher (this is important if the "percentage of winning score" tiebreaker is usded). Running out of time (i.e. time out) is a forfeit and receives a score of zero.
A30: 7 | C30: "Standings" tab - how to update:
B31: a | C31: For each finished game, add 1 to the finishing rank that corresponds to each player. The "Pts" and "Avg" columns will update automatically.
B33: b | C33: Sort: Select all 7 names, and drag to include all the game columns (i.e. 3rd place 3p game). Right-click, sort. Then select Z to A (highest to lowest) and by the "Avg" column.
B35: c | C35: Ties: If players tie, add 1, split equally between the number of shared positions, for each player. (Example 1: if a two way tie for first, add 0.5 to both the 1st and 2nd place columns for both players. Example 2: if a 3-way tie for last (4p game), add 0.333 to the 2nd, 3rd, and 4th columns for all 3 players that tied)
C39: ** Season End **
A40: 8 | C40: Sort all Divisions:
B41: a | C41: Select a Div (be sure it's all 7 rows of names and all 9 columns of data: names through final 3p slot)
B42: b | C42: Right click highlighted cells, select sort, choose descending (highest on top) by the column labeled "Pts"
B44: c | C44: This will now automatically reflect in the "End List" for next season. (see point 2-f, scaling, to ensure the "End List" properly reflects divisions with more than 7 players)

Sheet Start List
A1: Rank | B1: Name | C1: League Place (prior season) | D1: This season (League) | F1: Loading List (user name) | G1: Facebook Name
A2: 1 | B2: LeonC | C2: 1-1-1 | D2: 1-1 | F2: LeonC | G2: Chen Yenjung | H2: S2 - 1st
A3: 2 | B3: Palino | C3: 1-1-2 | D3: 1-1 | F3: Palino | G3: Palo Kaiser | H3: S2 - 2nd
A4: 3 | B4: BlixLT | C4: 1-1-3 | D4: 1-1 | F4: BlixLT | G4: Martynas Limontas | H4: S2 - 3rd
A5: 4 | B5: AaronGreen | C5: 1-1-4 | D5: 1-1 | F5: AaronGreen | G5: Aaron Green | H5: S2 - 4th
A6: 5 | B6: Toper | C6: 1-1-5 | D6: 1-1 | F6: Toper | G6: Chris Maloof | H6: S1 - 2nd
A7: 6 | B7: JCleek | C7: 2-1-1 | D7: 1-1 | F7: JCleek | G7: Jon Cleek | H7: S2 - 6th
A8: 7 | B8: Grogmir | C8: 2-2-1 | D8: 1-1 | F8: Grogmir | G8: Krzysiek Pytlak | H8: S2 - 7th
A9: 8 | B9: Frotes | C9: 1-1-6 | D9: 42767 | F9: Frotes | G9: Jack Liu | H9: S2 - 8th
A10: 9 | B10: qhung49 | C10: 1-1-7 | D10: 42768 | F10: qhung49 | G10: Hung Mai | H10: S2 - 9th
A11: 10 | B11: Aquir | C11: 3-1-1 | D11: 42768 | F11: Aquir | G11: Tamas Fekete | H11: S2 - 10th
A12: 11 | B12: FlyingDutchman | C12: 3-2-1 | D12: 42767 | F12: FlyingDutchman | G12: Florian Ergang | H12: S2 - 11th (tied)
A13: 12 | B13: GregoryD | C13: 3-3-1 | D13: 42767 | F13: GregoryD | G13: Grzegorz Dorozik | H13: S2 - 11th (tied)
A14: 13 | B14: jamiu5 | C14: 3-1-2 (WC) | D14: 42768 | F14: jamiu5 | G14: James Siqueira | H14: S2 - 13th (tied)
A15: 14 | B15: ChipsAhoya | C15: 2-1-2 | D15: 42768 | F15: ChipsAhoya | G15: Eric Rodawig | H15: S2 - 13th (tied)
A16: 15 | B16: Wartin | C16: 2-2-2 | D16: 42767 | F16: Wartin | G16: Martin Havrila | H16: S2 - 15th
A17: 16 | B17: Andras | C17: 2-1-3 | D17: 42767 | F17: Andras | G17: Gyurefi Andras | H17: S2 - 17th
A18: 17 | B18: nachof | C18: 2-2-3 | D18: 42768 | F18: nachof | G18: Nacho Facello | H18: S2 - 18th
A19: 18 | B19: Greenilocks | C19: 2-1-4 | D19: 42768 | F19: Greenilocks | G19: Gerard Sweeney | H19: S2 - 19th
A20: 19 | B20: Cefrebunda | C20: 2-2-4 | D20: 42767 | F20: Cefrebunda | G20: Papp Istvan | H20: S2 - 20th
... A43: 42 | B43: hihihiji | C43: 3-3-5 | D43: 42797 | F43: hihihiji | G43: Michael Tse | H43: N/A - Rank 23
A44: 43 | B44: robster | D44: 42826 | F44: robster | G44: Robin Van Dalen | H44: N/A - Rank 23
A45: 44 | B45: Sjir | D45: 42827 | F45: Sjir | G45: Hoeijmakers | H45: N/A - Rank 20
A46: 45 | B46: BillyPilgrim | D46: 42827 | F46: BillyPilgrim | G46: Amy (Wes) Bandy | H46: N/A - Rank 17
A47: 46 | B47: Monik | D47: 42826 | F47: Monik | G47: Laimonas Urbutis | H47: N/A - Rank 16
A48: 47 | B48: Pandaiga | D48: 42826 | F48: Pandaiga | G48: Ghengis Coin | H48: N/A - Rank 15
A49: 48 | B49: JimmyLin | D49: 42827 | F49: JimmyLin | G49: 林俊吉 | H49: N/A - Rank 15
A50: 49 | B50: Peaceminusone | D50: 42827 | F50: Peaceminusone | G50: Shikamaru Kepin | H50: N/A - Rank 15
A51: 50 | B51: Thomas91 | D51: 42826 | F51: Thomas91 | G51: Thomas de Bel | H51: N/A - Rank 15
A52: 51 | B52: 12thManStanding | D52: 42826 | F52: 12thManStanding | G52: Colin Bowler | H52: N/A - Rank 13
A53: 52 | B53: kissfish | D53: 42827 | F53: kissfish | G53: John Smith | H53: N/A - Rank 11
A54: 53 | B54: Backburner | D54: 42827 | F54: Backburner | G54: Samah Abdel Khalek | H54: N/A - Rank 11
A55: 54 | B55: Eroticus | D55: 42826 | F55: Eroticus | G55: Erot Igore | H55: N/A - Rank 5
... A57: 56 | B57: DrRerNate | D57: 42827 | F57: DrRerNate | G57: Nate Wasser | H57: N/A - Rank 1
A58: 57
A59: 58
A60: 59
A61: 60
A62: 61
A63: 62
...

Sheet End List
A1: Rank | B1: Name | C1: Division - Place | D1: Next Seas Div | F1: Ordering Rules:
A2: 1 | B2: =Standings!B4 -> LeonC | C2: 1-1-1 | D2: 1-1 | F2: •Starting at the top, all divisions will have exactly 7 players. Bottom divisions may have 8 or 9 to accomodate a season with total players a non multiple of 7.
A3: 2 | B3: =Standings!B15 -> Frotes | C3: 2-1-1 | D3: 1-1
A4: 3 | B4: =Standings!M15 -> ChipsAhoya | C4: 2-2-1 | D4: 1-1
A5: 4 | B5: =Standings!B5 -> AaronGreen | C5: 1-1-2 | D5: 1-1 | F5: •Player can never move two divisions up or down in a single season.
A6: 5 | B6: =Standings!B6 -> Toper | C6: 1-1-3 | D6: 1-1 | F6: •Relegated players: bottom two in league will always fall exactly one division.
A7: 6 | B7: =Standings!B7 -> Palino | C7: 1-1-4 | D7: 1-1 | F7: •Promoted players: league winner (and wild card if applicable, e.g. Division 3) will always move up exactly one division.
A8: 7 | B8: =Standings!B8 -> JCleek | C8: 1-1-5 | D8: 1-1
A9: 8 | B9: =Standings!B16 -> FlyingDutchman | C9: 2-1-2 | D9: 42767 | F9: •Middle players (neither promoted nor demoted): stay in same division unless, due to players leaving, should move up (similar to a wild card). If too many returning players, a middle player can be relagated.
A10: 9 | B10: =Standings!M16 -> Aquir | C10: 2-2-2 | D10: 42768
A11: 10 | B11: =Standings!B17 -> GregoryD | C11: 2-1-3 | D11: 42768
A12: 11 | B12: =Standings!M17 -> qhung49 | C12: 2-2-3 | D12: 42767
A13: 12 | B13: =Standings!B18 -> albinsix | C13: 2-1-4 | D13: 42767
A14: 13 | B14: =Standings!M18 -> nachof | C14: 2-2-4 | D14: 42768
A15: 14 | B15: =Standings!B9 -> Grogmir | C15: 1-1-6 | D15: 42768
A16: 15 | B16: =Standings!B10 -> BlixLT | C16: 1-1-7 | D16: 42767
A17: 16 | B17: =Standings!B26 -> pajada | C17: 3-1-1 | D17: 42767
A18: 17 | B18: =Standings!M26 -> JeremyBrokaw | C18: 3-2-1 | D18: 42768
A19: 18 | B19: =Standings!Y26 -> hihihiji | C19: 3-3-1 | D19: 42768
A20: 19 | B20: =Standings!B27 -> swxnw | C20: 3-1-2 (WC) | D20: 42767
A21: 20 | B21: =Standings!B19 -> Wartin | C21: 2-1-5 | D21: 42767
A22: 21 | B22: =Standings!M19 -> jamiu5 | C22: 2-2-5 | D22: 42768
A23: 22 | B23: =Standings!B20 -> Andras | C23: 3-2-2 | D23: 42795
A24: 23 | B24: =Standings!M20 -> norkle | C24: 3-3-2 | D24: 42796
A25: 24 | B25: =Standings!B21 -> Cefrebunda | C25: 3-1-3 | D25: 42797
A26: 25 | B26: =Standings!M21 -> Greenilocks | C26: 3-2-3 | D26: 42797
A27: 26 | B27: =Standings!B37 -> robster | C27: 3-3-3 | D27: 42796
A28: 27 | B28: =Standings!M37 -> DrRerNate | C28: 3-1-4 | D28: 42795
A29: 28 | B29: =Standings!Y37 | C29: 3-2-4 | D29: 42795
A30: 29 | B30: =Standings!B46 | C30: 3-3-4 | D30: 42796
A31: 30 | B31: =Standings!M46 | C31: 2-1-6 | D31: 42797
A32: 31 | B32: =Standings!B38 -> Pandaiga | C32: 2-2-6 | D32: 42797
A33: 32 | B33: =Standings!M27 -> invalidName | C33: 2-1-7 | D33: 42796
A34: 33 | B34: =Standings!Y27 -> Woodenman | C34: 2-2-7 | D34: 42795
A35: 34 | B35: =Standings!B28 -> PhiTrigger | C35: 4-1-1 | D35: 42795
A36: 35 | B36: =Standings!M28 -> takusto_ii | C36: 4-2-1 | D36: 42796
A37: 36 | B37: =Standings!Y28 -> Circadia | C37: 4-3-1 | D37: 42797
A38: 37 | B38: =Standings!B29 -> bcnoexceptions | C38: 4-4-1 | D38: 42797
A39: 38 | B39: =Standings!M29 -> Ivantz | C39: 4-5-1 | D39: 42796
A40: 39 | B40: =Standings!Y29 -> Werlix | C40: 4-1-2 (WC) | D40: 42795
...

Sheet Scaling
B1: Scaling to accomodate numbers not divisible by 7
B2: Total plyrs | C2: Adjustments (i.e. add "x" to a League)
C3: 42736 | D3: 42767 | E3: 42768 | F3: 42795 | G3: 42796 | H3: 42797 | I3: 42826 | J3: 42827 | K3: 42828 | L3: 42829 | M3: 42830 | N3: 42856 | O3: 42857 | P3: 42858 | Q3: 42859 | R3: 42860 | S3: 42861 | T3: 42862 | U3: 42863 | V3: 42887 | W3: 42888
B4: 22 | C4: 7 | D4: 14 | E4: 21 | F4: 28 | G4: 35 | H4: 42 | I4: 49 | J4: 56 | K4: 63 | L4: 70 | M4: 77 | N4: 84 | O4: 91 | P4: 98 | Q4: 105 | R4: 112 | S4: 119 | T4: 126 | U4: 133
A5: =sum(C5:U5) -> 2 | B5: 23 | D5: 1 | E5: 1
A6: =sum(C6:U6) -> 3 | B6: 24 | D6: 1 | E6: 2 | J6: Rules: (add in this order, as needed, until maxed, then continue to next step)
A7: =sum(C7:U7) -> 4 | B7: 25 | D7: 2 | E7: 2 | K7: +1 to all lowest level divisions.
A8: =sum(C8:U8) -> 5 | B8: 26 | C8: 1 | D8: 2 | E8: 2 | K8: +2 to all lowest level divisions.
A9: =sum(C9:U9) -> 6 | B9: 27 | C9: 2 | D9: 2 | E9: 2 | K9: +1 to ALL (if possible) divisions one level higher, with remaining extras added to lowest level divisions.
A10: =sum(C10:U10) -> 0 | B10: 28
A11: =sum(C11:U11) -> 1 | B11: 29 | F11: 1
A12: =sum(C12:U12) -> 2 | B12: 30 | F12: 2
A13: =sum(C13:U13) -> 3 | B13: 31 | D13: 1 | E13: 1 | F13: 1
A14: =sum(C14:U14) -> 4 | B14: 32 | D14: 1 | E14: 1 | F14: 2
A15: =sum(C15:U15) -> 5 | B15: 33 | D15: 1 | E15: 2 | F15: 2
A16: =sum(C16:U16) -> 6 | B16: 34 | D16: 2 | E16: 2 | F16: 2
A17: =sum(C17:U17) -> 0 | B17: 35
A18: =sum(C18:U18) -> 1 | B18: 36 | G18: 1
A19: =sum(C19:U19) -> 2 | B19: 37 | F19: 1 | G19: 1
A20: =sum(C20:U20) -> 3 | B20: 38 | F20: 1 | G20: 2
A21: =sum(C21:U21) -> 4 | B21: 39 | F21: 2 | G21: 2
A22: =sum(C22:U22) -> 5 | B22: 40 | D22: 1 | E22: 1 | F22: 1 | G22: 2
A23: =sum(C23:U23) -> 6 | B23: 41 | D23: 1 | E23: 1 | F23: 2 | G23: 2
A24: =sum(C24:U24) -> 0 | B24: 42
A25: =sum(C25:U25) -> 1 | B25: 43 | H25: 1
A26: =sum(C26:U26) -> 2 | B26: 44 | G26: 1 | H26: 1
A27: =sum(C27:U27) -> 3 | B27: 45 | F27: 1 | G27: 1 | H27: 1
A28: =sum(C28:U28) -> 4 | B28: 46 | F28: 1 | G28: 1 | H28: 2
A29: =sum(C29:U29) -> 5 | B29: 47 | F29: 1 | G29: 2 | H29: 2
A30: =sum(C30:U30) -> 6 | B30: 48 | F30: 2 | G30: 2 | H30: 2
A31: =sum(C31:U31) -> 0 | B31: 49
A32: =sum(C32:U32) -> 1 | B32: 50 | I32: 1
A33: =sum(C33:U33) -> 2 | B33: 51 | I33: 2
A34: =sum(C34:U34) -> 3 | B34: 52 | F34: 1 | G34: 1 | H34: 1
A35: =sum(C35:U35) -> 4 | B35: 53 | F35: 1 | G35: 1 | H35: 1 | I35: 1
A36: =sum(C36:U36) -> 5 | B36: 54 | F36: 1 | G36: 1 | H36: 1 | I36: 2
A37: =sum(C37:U37) -> 6 | B37: 55 | F37: 1 | G37: 1 | H37: 2 | I37: 2
A38: =sum(C38:U38) -> 0 | B38: 56
A39: =sum(C39:U39) -> 1 | B39: 57 | J39: 1
A40: =sum(C40:U40) -> 2 | B40: 58 | I40: 1 | J40: 1
...
